Workbook
Name _____xlnm._FilterDatabase: #REF!
Name _____xlnm.Print_Titles: #REF!
Name _____xlnm.Print_Titles_1: #REF!
Name ____xlnm._FilterDatabase: #REF!
Name ____xlnm.Print_Titles: #REF!
Name ____xlnm.Print_Titles_1: #REF!
Name ___xlnm._FilterDatabase: #REF!
Name ___xlnm.Print_Titles: #REF!
Name ___xlnm.Print_Titles_1: #REF!
Name __xlnm._FilterDatabase: #REF!
Name __xlnm.Print_Titles: #REF!
Name __xlnm.Print_Titles_1: #REF!
Name A: #REF!
Name ACT_FIJOS_VALOR: #REF!
Name AJUSTE_REAJ_FIS_AF: #REF!
Name año: #REF!
Name cajaç: #REF!
Name CALDECNM: #REF!
Name Caracter: #REF!
Name CIIU: #REF!
Name CIIUNM: #REF!
Name CLASEDEC: #REF!
Name CLASEDECNM: #REF!
Name CODADMONNM: #REF!
Name CODDOCSNM: #REF!
Name Codigos: #REF!
Name Comprobantes: #REF!
Name convencion: #REF!
Name cxc: #REF!
Name DEPTOSNM: #REF!
Name DIVIPOL: #REF!
Name DIVIPOL1: #REF!
Name DIVIPOLCOD: #REF!
Name DIVIPOLNM: #REF!
Name Excel_BuiltIn_Print_Titles: #REF!
Name Excel_BuiltIn_Print_Titles_1: #REF!
Name G: #REF!
Name gActEcono: #REF!
Name gAdmon: #REF!
Name gAño: #REF!
Name gApe1Dec: #REF!
Name gApe1Rev: #REF!
Name gApe2Dec: #REF!
Name gApe2Rev: #REF!
Name GB: #REF!
Name gCalDec: #REF!
Name gCedDec: #REF!
Name gCedRev: #REF!
Name gClaseDec: #REF!
Name gDeclaraPrimerVez: #REF!
Name gDepto: #REF!
Name gDireccion: #REF!
Name gExentoRtaPres: #REF!
Name gFechaDecCor: #REF!
Name gMetValInv: #REF!
Name gMun: #REF!
Name gNIT: #REF!
Name gNom1Dec: #REF!
Name gNom1Rev: #REF!
Name gNom2Dec: #REF!

Sheet Eventos de riesgos
B1: REFERENCIA | C1: Año | D1: Mes | E1: FECHA INICIO | F1: FECHA FINALIZACION | G1: FECHA DESCUBRIMIENTO | H1: DESCRIPCION EVENTO | I1: CUANTIA | J1: CUANTIA TOTAL RECUPERADA | K1: CUANTIA RECUPERADA SEGUROS | L1: CLASE EVENTO NIVEL 1 | M1: CLASE EVENTO NIVEL 2 | N1: CLASE EVENTO NIVEL 3 | O1: CUENTA CONTABLE | P1: FECHA CONTABILIZACION | Q1: SERVICIO / PRODUCTO | R1: CANAL ATENCION CLIENTE | S1: NIT FUNCIONARIO REPORTE EVENTO | T1: NOMBRE FUNCIONARIO REPORTE EVENTO | U1: EMAIL FUNCIONARIO REPORTE EVENTO | V1: ESTADO EVENTO | W1: REVISION EVENTO | X1: CATEGORÍA 4 (Interna) | Y1: RIESGOS | Z1: TAREAS | AA1: PERDIDA TOTAL | AB1: DESCRIPCIÓN DE RIESGO | AC1: EVENTO (Qué pasó) | AD1: CAUSA (Por qué ocurrió) | AE1: CONSECUENCIA (Impactos)
B2: 1 | C2: 2021 | D2: Dic | E2: 44440.835 | F2: 44531.835 | G2: 44531.835 | H2: Caso Febor tiene contratado los servicios de Visionamos para operaciones electrónicas. El pasado 1 de septiembre de 2020, Visionamos ejecutó un proceso en cola de aplicación de nomina erróneamente, este proceso se ejecutó más de una vez debido a desconexiones tecnológicas donde no se evidenció la corrida del proceso inicial y se procedió a correrlo 2 veces mas, ocasionando aumento en los saldos y obligando a reprocesar con reversiones de saldos. En este proceso se afectó 137 asociados por un valor total de $ 344.885.519, no hubo pérdidas económicas ya que los dineros abonados no habían sido retirados de las cuentas por parte de los asociados. Desde Febor se operó un reintegro masivo para recuperar los dineros, sin embargo, siendo Visionamos el responsable material, se observó que no intervino en el reproceso y que por otro lado se identificó la falla hasta diciembre de 2021 por parte del área operativa (1 año y 3 meses después), esto genera alertas tales como: Riesgo operativo de terceros, fallas en la comunicación y flujos operativos con terceros, reputación y credibilidad de la Cooperativa. Acciones Reversión de saldos Realizar reversión de las operaciones erradas. Monitoreo permanente de las operaciones electrónicas, puede que las desconexiones de interface se repitan pero la Cooperativa debe conocerlo inmediatamente. Es necesario soporte permanente también desde visionamos. Jefe de Operaciones | I2: 344885519 | J2: 344885519 | K2: 0 | L2: 7 - Ejecución y Administración de Procesos | M2: 76 - Proveedores | N2: 763 - Incumplimiento de las Actividades Contratadas | P2: 44561 | Q2: Ahorros voluntarios | R2: Ninguno | S2: 52974192 | T2: Ingrid Yamile Polo Caita | U2: operaciones@febor.coop | V2: Aprobado | W2: 16/02/2022 20:08:19: Riesgo. Pérdidas económicas por fallas operativas que implica la relación e intervención con proveedores y/o terceros y pérdida de imagen y confianza de los asociados si se ven afectados sus productos financieros a causa de actividades erradas desde la Cooperativa. | X2: Falla en operaciones electrónicas originadas por el proveedor | Z2: =+COUNTIF('Eventos-Tareas'!$D$22:$D$1048576,'Eventos de riesgos'!$B2) -> 1 | AA2: =+'Eventos de riesgos'!$I2-'Eventos de riesgos'!$J2-'Eventos de riesgos'!$K2 -> 0 | AB2: El proveedor Visionamos ejecutó múltiples veces un proceso de aplicación de nómina por desconexiones tecnológicas, afectando los saldos de 137 asociados por $344.885.519. La falla no fue detectada oportunamente por el área operativa, generando riesgo reputacional y operativo. | AC2: El proveedor Visionamos ejecutó erróneamente el proceso de aplicación de nómina en múltiples ocasiones, generando incrementos indebidos en los saldos de 137 asociados por un valor total de $344.885.519. | AD2: Desconexiones tecnológicas en los sistemas del proveedor impidieron verificar la ejecución inicial del proceso, llevando a su repetición. La falla no fue identificada por el área operativa de Febor sino hasta 15 meses después del evento. | AE2: Afectación de saldos de 137 asociados. Aunque no hubo pérdida económica definitiva, se requirió un reintegro masivo. Se generaron alertas de riesgo operativo con terceros, fallas en comunicación y riesgo reputacional para la Cooperativa.
B3: 2 | C3: 2021 | D3: Oct | E3: 44286 | F3: 44286 | G3: 44489 | H3: Caso Sobre los primeros días de marzo de 2021, 35 asociados hicieron operaciones con su tarjeta débito que en total sumó $7.943.416. Se presentó fallas tecnológicas, desconexión entre los aplicativos y dichas operaciones nunca fueron descontadas de los ahorros voluntarios de los asociados. Por otro lado, se añade que al momento de realizar conciliaciones, no se verificó estas operaciones y en el mes de octubre cuando se detectó la falla, varios asociados ya no tenían este dinero es sus cuentas de ahorro para realizar el cobro correspondiente. Acciones De los $7.943.416 que sumó el total de las transacciones, se recuperó $4.365.767 quedando un valor por recuperar de $3.607.649. Revisar las operaciones de los asociados afectados, conciliar y recuperar los dineros de las cuentas de ahorro voluntario y para quienes ya no contaban con el recurso ir recuperando de manera paulatina. | I3: 7943416 | J3: 4365767 | K3: 0 | L3: 6 - Fallas Tecnologicas | M3: 61 - Sistemas | N3: 614 - Interrupción en el Suministro de un Servicio Público que Ocasiones Falla en los Sistemas | P3: 44500 | Q3: Ahorros voluntarios | R3: Ninguno | S3: 52974192 | T3: INGRID YAMILE POLO CAITA | U3: operaciones@febor.coop | V3: Aprobado | W3: 18/02/2022 15:52:17: Riesgo identificado - Pérdidas económicas por fallas tecnológicas entra los aplicativos que conectan la operación de la Cooperativa. | X3: Falla en operaciones electrónicas originadas por el proveedor | Z3: =+COUNTIF('Eventos-Tareas'!$D$22:$D$1048576,'Eventos de riesgos'!$B3) -> 1 | AA3: =+'Eventos de riesgos'!$I3-'Eventos de riesgos'!$J3-'Eventos de riesgos'!$K3 -> 3577649 | AB3: Fallas tecnológicas en la conexión entre aplicativos impidieron que 35 operaciones con tarjeta débito por $7.943.416 fueran descontadas de las cuentas de ahorro voluntario. La falla no fue detectada en las conciliaciones, generando una pérdida no recuperada de $3.577.649. | AC3: 35 asociados realizaron operaciones con tarjeta débito por un total de $7.943.416, las cuales no fueron descontadas de sus cuentas de ahorro voluntario debido a una falla en la conexión entre aplicativos. | AD3: Falla tecnológica por desconexión entre los sistemas transaccionales. Adicionalmente, las conciliaciones periódicas no detectaron oportunamente las operaciones pendientes de aplicar. | AE3: Pérdida económica de $3.577.649 no recuperada. Se logró recuperar $4.365.767 de los $7.943.416 totales. Varios asociados ya no contaban con los saldos suficientes al momento del descubrimiento.
B4: 3 | C4: 2021 | D4: Dic | E4: 44529 | F4: 44533 | G4: 44533 | H4: Caso El 29 de noviembre, el área de operaciones ejecutó el proceso acostumbrado de aplicación de nominas de Colpensiones, tomando la plantilla oficial publicada en la página Web de Colpensiones. El 3 de diciembre, cuando el área de operaciones verificó el proceso junto con el área contable se hallaron diferencias con el reporte aplicado Se evidenció que la plantilla utilizada para dicha operación era errada, (error que reconoció Colpensiones y posteriormente publicó la plantilla corregida) y que faltaba información por suministrar. En este proceso se procedió a realizar el cargue nuevamente y no se generaron pérdidas económicas para la Cooperativa. Acciones Corregir las operaciones ejecutadas de manera errónea, de forma urgente. Medida de autocontrol por parte del analista, debe revisar plantillas y versiones oficiales antes de los cargues | I4: 0 | J4: 0 | K4: 0 | L4: 7 - Ejecución y Administración de Procesos | M4: 71 - Recepción, Ejecución y Mantenimiento de Operaciones | N4: 717 - Problema en el Mantenimiento de Datos de Referencia | P4: 44561 | Q4: Varios tipos de crédito | R4: Ninguno | S4: 52974192 | T4: INGRID YAMILE POLO CAITA | U4: operaciones@febor.coop | V4: Aprobado | W4: 18/02/2022 15:59:23: Identificación de riesgo- Pérdidas económicas por operaciones erradas en la aplicación de nomina. | X4: Error en aplicación de nómina Colpensiones | Z4: =+COUNTIF('Eventos-Tareas'!$D$22:$D$1048576,'Eventos de riesgos'!$B4) -> 1 | AA4: =+'Eventos de riesgos'!$I4-'Eventos de riesgos'!$J4-'Eventos de riesgos'!$K4 -> 0 | AB4: El área de operaciones aplicó la nómina de Colpensiones usando una plantilla errónea publicada por la entidad, lo que generó diferencias contables. Se realizó el reproceso sin pérdidas económicas para la Cooperativa. | AC4: Se aplicó la nómina de Colpensiones utilizando una plantilla incorrecta publicada en la página web oficial de Colpensiones, generando diferencias en el reporte aplicado detectadas días después por el área de operaciones y contabilidad. | AD4: Colpensiones publicó una plantilla con errores en su página web oficial, la cual fue utilizada por el área de operaciones de Febor sin validación previa de su versión o vigencia. | AE4: Necesidad de reprocesar el cargue de nómina. No se generaron pérdidas económicas para la Cooperativa, pero el evento evidenció la necesidad de controles de autocontrol en la verificación de plantillas antes del procesamiento.
B5: 4 | C5: 1900 | D5: Ene | H5: Prueba eliminada por verificación en proceso de implementación SARO SIAR | L5: Prueba | M5: Prueba | Q5: Ninguno | R5: Ninguno | Z5: =+COUNTIF('Eventos-Tareas'!$D$22:$D$1048576,'Eventos de riesgos'!$B5) -> 0 | AA5: =+'Eventos de riesgos'!$I5-'Eventos de riesgos'!$J5-'Eventos de riesgos'!$K5 -> 0 | AB5: 0 | AC5: 0 | AD5: 0 | AE5: 0
B6: 5 | C6: 2022 | D6: Ene | E6: 44562 | F6: 44562 | G6: 44562 | H6: Caso Personas inescrupulosas crearon una página web www.coopfebor.com falsa para ofrecer préstamos de libre inversión, aprovechándose del buen nombre de Febor. Realizaron publicidad de oferta de servicios mediante cartas dirigidas y por la línea de WhatsApp 3123312790 donde solicitan envío de información al correo de gerencia@coopfebor.com con el fin de obtener tal servicio. En dicha pagina web se publicó la dirección real de Febor para crear confianza, Febor acudió inmediatamente a la publicación oficial de la novedad por los canales oficiales dirigida a los asociados y tramitó las denuncias correspondientes. El proceso de suplantación no surgió efecto, no se identifican asociados víctimas de fraude en este evento. Acciones Comunicación y alerta inmediata a través de los canales oficiales de la Cooperativa para prevenir a los asociados de ser victimas de fraude. Verificación permanente de sitios web sospechosos con información básica de Febor. | I6: 0 | J6: 0 | K6: 0 | L6: 2 - Fraude Externo | M6: 22 - Hurto y Fraude | N6: 222 - Falsificación | P6: 44592 | Q6: Crédito de libre inversión | R6: Canales de comunicación virtual | S6: 1033706838 | T6: Diana Maribel Fonseca Gómez | U6: direccion.riesgos@febor.coop | V6: Aprobado | W6: 18/02/2022 16:14:05: Transacción de riesgo- Pérdida de imagen y reputación debido a suplantaciones realizadas por personas inescrupulosas. | X6: Suplantación de página web de Febor | Z6: =+COUNTIF('Eventos-Tareas'!$D$22:$D$1048576,'Eventos de riesgos'!$B6) -> 1 | AA6: =+'Eventos de riesgos'!$I6-'Eventos de riesgos'!$J6-'Eventos de riesgos'!$K6 -> 0 | AB6: Terceros crearon una página web falsa suplantando a Febor para ofrecer préstamos, utilizando el nombre, dirección real y canales de comunicación de la Cooperativa. No se identificaron asociados víctimas, pero se generó riesgo reputacional. | AC6: Personas inescrupulosas crearon la página web www.coopfebor.com suplantando a Febor para ofrecer préstamos de libre inversión, difundiendo la oferta mediante cartas y WhatsApp con datos reales de la Cooperativa. | AD6: Aprovechamiento del buen nombre de Febor por parte de terceros con fines fraudulentos, mediante la creación de canales digitales falsos con información oficial de la Cooperativa. | AE6: Riesgo reputacional para la Cooperativa. No se identificaron asociados víctimas de fraude. Febor realizó alertas por canales oficiales y radicó las denuncias correspondientes.
B7: 6 | C7: 1900 | D7: Ene | H7: Prueba eliminada por verificación en proceso de implementación SARO SIAR | L7: Prueba | M7: Prueba | O7: Ninguna | Q7: Ninguno | R7: Ninguno | Z7: =+COUNTIF('Eventos-Tareas'!$D$22:$D$1048576,'Eventos de riesgos'!$B7) -> 0 | AA7: =+'Eventos de riesgos'!$I7-'Eventos de riesgos'!$J7-'Eventos de riesgos'!$K7 -> 0 | AB7: 0 | AC7: 0 | AD7: 0 | AE7: 0
B8: 7 | C8: 1900 | D8: Ene | H8: Prueba eliminada por verificación en proceso de implementación SARO SIAR | L8: Prueba | M8: Prueba | O8: Ninguna | Q8: Ninguno | R8: Ninguno | Z8: =+COUNTIF('Eventos-Tareas'!$D$22:$D$1048576,'Eventos de riesgos'!$B8) -> 0 | AA8: =+'Eventos de riesgos'!$I8-'Eventos de riesgos'!$J8-'Eventos de riesgos'!$K8 -> 0 | AB8: 0 | AC8: 0 | AD8: 0 | AE8: 0
B9: 8 | C9: 2022 | D9: Feb | E9: 43870 | F9: 43871 | G9: 44602 | H9: Caso El 09 de febrero de 2022 se presentaron fallas en la conexión de internet y en el PBX a partir de las 6:00pm, ocasionado por un daño en el switch (un dispositivo de interconexión utilizado para conectar equipos en red). Se realizó el proceso de restablecimiento del sistema y opera con normalidad a partir de las 8:30 am del 10 de febrero 2022. Para garantizar continuidad de la operación, se reemplazará el dispositivo de interconexión con los recursos presupuestados para el mantenimiento preventivo y/o correctivo de equipos e infraestructura tecnológica. No se registran pérdidas económicas que deba asumir la Cooperativa. Acciones Reemplazar el switch dañado para garantizar nuevamente la conectividad. | I9: 0 | J9: 0 | K9: 0 | L9: 6 - Fallas Tecnologicas | M9: 61 - Sistemas | N9: 613 - Pérdida por Fallas en Telecomunicaciones | O9: Ninguna | P9: 44620 | Q9: Ninguno | R9: Comunicación por PBX | S9: 53166187 | T9: Johana Paola Cortés Gómez | U9: direccion.sas@febor.coop | V9: Aprobado | W9: 18/02/2022 16:53:31: Transacción de riesgo - Insatisfacción de los asociados por no prestar oportunamente los servicios mediante los canales telefónicos dado que las fallas tecnológicas interrumpen este medio de comunicación. | X9: Indisponibilidad PBX | Z9: =+COUNTIF('Eventos-Tareas'!$D$22:$D$1048576,'Eventos de riesgos'!$B9) -> 1 | AA9: =+'Eventos de riesgos'!$I9-'Eventos de riesgos'!$J9-'Eventos de riesgos'!$K9 -> 0 | AB9: Daño en el switch de interconexión de red provocó la indisponibilidad del servicio de internet y PBX durante aproximadamente 14 horas, afectando la prestación del servicio a los asociados y la operación de la Cooperativa. | AC9: El 9 de febrero de 2022, a partir de las 6:00 p.m., se presentó falla en la conexión de internet y en el PBX de la Cooperativa, ocasionada por el daño en el switch de interconexión de red. El servicio fue restablecido a las 8:30 a.m. del día siguiente. | AD9: Daño físico en el switch de interconexión de red, dispositivo que conecta los equipos a la red interna y externa de la Cooperativa. | AE9: Indisponibilidad del servicio de internet y PBX durante aproximadamente 14,5 horas. No se registraron pérdidas económicas, pero se generó insatisfacción por la interrupción en la atención telefónica a los asociados.
B10: 9 | C10: 2022 | D10: Feb | E10: 44606 | F10: 44607 | G10: 44606 | H10: Caso El día 14 de febrero 2022 el asociado José Neira Ochoa identificado con CC 170562291 reportó sobre las 4:30 pm a Febor que intentaban extraer dinero de su cuenta de ahorros voluntarios sin su consentimiento. Al indagar y averiguar la situación expuesta por el asociado, se logró identificar dos personas que intentaban extraer $12 millones de pesos, y se bloqueó la aplicación del retiro inmediatamente, de igual al día siguiente, el asociado reportó que en la madrugada del 15 de febrero también tuvo intento de robo por $20 millones por uno de las personas identificadas. El Asociado José Neira argumenta que esta persona es un asesor de una empresa de telefonía donde solicitó un servicio, y él confiado entregó su celular, por tal motivo este asesor tuvo acceso a su App móvil transaccional e inicio sus intentos de fraude. Febor hizo los bloqueos correspondientes sobre los productos del asociado para evitar este hurto y brindó la información pertinente para que pudiera iniciar un proceso de denuncia formal ante las autoridades competentes. Acciones Realizar el bloqueo inmediato de las cuentas y productos del asociado, asesorar al asociado para el restablecimiento de contraseñas Comunicar y alertar de manera preventiva a los asociados para que cuiden su información y equipos de uso personal. Brindar información al asociado con respecto de los intentos de fraude y asesoramiento para que presente la denuncia correspondiente. | I10: 0 | J10: 0 | K10: 0 | L10: 2 - Fraude Externo | M10: 22 - Hurto y Fraude | N10: 221 - Robo o Hurto | O10: Ninguna | P10: 44620 | Q10: Ahorros voluntarios | R10: Aplicación móvil (App Febor) | S10: 1016071699 | T10: JOHAN SANTIAGO CRUZ MARTÍN | U10: Analista.operativo2@febor.coop | V10: Aprobado | W10: 18/02/2022 16:58:10: Transacción de riesgo- Pérdida de imagen y credibilidad con respecto de la seguridad de nuestros mecanismos de seguridad tecnológica y oportunidad de respuesta ante situaciones de posible fraude. | X10: Suplantación y fraude a asociados | Z10: =+COUNTIF('Eventos-Tareas'!$D$22:$D$1048576,'Eventos de riesgos'!$B10) -> 2 | AA10: =+'Eventos de riesgos'!$I10-'Eventos de riesgos'!$J10-'Eventos de riesgos'!$K10 -> 0 | AB10: Terceros accedieron de forma no autorizada a la App móvil transaccional de un asociado e intentaron realizar retiros por $32 millones desde su cuenta de ahorros voluntarios. Los intentos fueron bloqueados oportunamente. | AC10: El asociado José Neira Ochoa reportó intentos de retiro no autorizados por $12 millones y posteriormente $20 millones desde su cuenta de ahorros voluntarios a través de la App móvil transaccional. Los retiros fueron bloqueados de manera oportuna. | AD10: El asociado entregó su celular a un asesor de telefonía quien accedió a la App móvil transaccional. La falta de control sobre el dispositivo personal del asociado expuso sus credenciales y acceso a los productos financieros. | AE10: No se registraron pérdidas económicas. Se realizaron bloqueos inmediatos sobre los productos del asociado. Se generó riesgo reputacional relacionado con la seguridad de los mecanismos tecnológicos y la capacidad de respuesta ante fraudes.
B11: 10 | C11: 2022 | D11: Ene | E11: 44556 | F11: 44564 | G11: 44564 | H11: Caso No se programó el débito automático de la asociada Olaine Salas Fuentes de su producto Línea temporal con un saldo e $6.500.000 y una cuota de $110.500, debido a que el proceso de programación de débitos automáticos no está automatizado, se realiza de forma manual agregando un listado oficial en Excel y por olvido del analista que administra dicha información, no se incorporó la programación del débito para esta obligación. La obligación vencía el 26 de diciembre /21 y se aplicó el débito hasta el día 3 de enero/22. Acciones Programar y ejecutar de manera inmediata el débito automático. Auditoría a los procesos de gestión de operaciones para identificar oportunidades de mejora en los diferentes procesos. | I11: 110500 | J11: 110500 | K11: 0 | L11: 7 - Ejecución y Administración de Procesos | M11: 71 - Recepción, Ejecución y Mantenimiento de Operaciones | N11: 711 - Exceso de Manualidad | O11: Ninguna | P11: 44592 | Q11: Crédito de consumo | R11: Ninguno | S11: 1016071699 | T11: JOHAN SANTIAGO CRUZ MARTÍN | U11: Analista.operativo2@febor.coop | V11: Aprobado | W11: 18/02/2022 16:48:20: Transacción de riesgo- Aumento de la cartera en mora por no aplicar oportunamente los descuentos de recaudo autorizados 18/02/2022 16:58:57: Transacción de riesgo- Aumento de la cartera en mora por no aplicar oportunamente los descuentos de recaudo autorizados | X11: Error en débitos automáticos | Z11: =+COUNTIF('Eventos-Tareas'!$D$22:$D$1048576,'Eventos de riesgos'!$B11) -> 1 | AA11: =+'Eventos de riesgos'!$I11-'Eventos de riesgos'!$J11-'Eventos de riesgos'!$K11 -> 0 | AB11: El débito automático de la cuota de una obligación crediticia no fue programado por error humano del analista responsable, generando un retraso de 8 días en el cobro y un vencimiento de la obligación. | AC11: No se programó el débito automático correspondiente a la cuota de $110.500 de la línea temporal de la asociada Olaine Salas Fuentes, cuya obligación vencía el 26 de diciembre de 2021. El débito fue aplicado hasta el 3 de enero de 2022. | AD11: El proceso de programación de débitos automáticos se realiza de forma manual mediante un listado en Excel. El analista responsable omitió incluir esta obligación en dicho listado. | AE11: Retraso de 8 días en el recaudo de la cuota. La obligación quedó registrada como vencida. El evento evidenció una debilidad en los controles del proceso manual de programación de débitos automáticos.
B12: 11 | C12: 2021 | D12: Dic | E12: 44535 | F12: 44536 | G12: 44536 | H12: Caso Se sobregiraron las cuentas de ahorros de aproximadamente 30 asociados por un total de $41.000.000 debido a que se realizaron operaciones de retiro el domingo 5 de diciembre/21 y la conexión entre Wog-Visionamos -Empacto no reflejó oportunamente aquellos giros efectuados. Las actualizaciones no quedan inmediatamente, se hacen 3 veces al día, pero el día del evento era fin de semana y el día siguiente, lunes 6 de diciembre/21 al realizar dichas actualizaciones se detecto el sobregiro. No se registra pérdidas económicas asumidas por la Cooperativa, se toman acciones inmediatas para la recuperación del dinero. Acciones Identificar los asociados con sobregiro para proceder a la recuperación de la operación o solicitud de la devolución del dinero. | I12: 41000000 | J12: 41000000 | K12: 0 | L12: 7 - Ejecución y Administración de Procesos | M12: 76 - Proveedores | N12: 763 - Incumplimiento de las Actividades Contratadas | O12: Ninguna | P12: 44561 | Q12: Ahorros voluntarios | R12: Ninguno | S12: 1016071699 | T12: JOHAN SANTIAGO CRUZ MARTÍN | U12: Analista.operativo2@febor.coop | V12: Aprobado | W12: 18/02/2022 16:43:37: Transacción de riesgo - Pérdidas económicas, de imagen y credibilidad en la ejecución de operaciones y transacciones, originado por fallas tecnológicas entre los aplicativos que conectan la operación de la Cooperativa. 18/02/2022 16:59:46: Transacción de riesgo- Pérdidas económicas, de imagen y credibilidad en la ejecución de operaciones y transacciones, originado por fallas tecnológicas entre los aplicativos que conectan la operación de la Cooperativa. | X12: Sobregiro de cuentas de ahorro voluntario | Z12: =+COUNTIF('Eventos-Tareas'!$D$22:$D$1048576,'Eventos de riesgos'!$B12) -> 1 | AA12: =+'Eventos de riesgos'!$I12-'Eventos de riesgos'!$J12-'Eventos de riesgos'!$K12 -> 0 | AB12: Falla en la conexión entre Wog, Visionamos y Empacto durante un fin de semana permitió retiros que generaron sobregiros en las cuentas de aproximadamente 30 asociados por $41 millones, detectados al día hábil siguiente. | AC12: El domingo 5 de diciembre de 2021, operaciones de retiro realizadas por aproximadamente 30 asociados no fueron reflejadas oportunamente en los sistemas por falla en la conexión entre Wog, Visionamos y Empacto, generando sobregiros por $41 millones. | AD12: La sincronización de operaciones se ejecuta tres veces al día, y al tratarse de un fin de semana, las actualizaciones no se realizaron con la oportunidad requerida, dejando pasar retiros que superaban los saldos reales disponibles. | AE12: Sobregiro en las cuentas de aproximadamente 30 asociados por un total de $41 millones. No se registraron pérdidas económicas asumidas por la Cooperativa, pero se requirieron acciones inmediatas para la recuperación del dinero.
B13: 12 | C13: 2022 | D13: Feb | E13: 44609.585 | F13: 44610.594 | G13: 44609.594 | H13: Caso El asociado WULFRAN ENRIQUE LOPEZ OJEDA identificado con cédula de ciudadanía 3726870, realizó un proceso de compra de cartera con la entidad Excelcredit, valiéndose de un paz y salvo valiéndose de la falsificación de un paz y salvo a nombre de Febor sobre los productos de crédito 1192902 y 111977 firmado por una persona que no trabaja en la Cooperativa (Beatriz Elene Henao Quintero). El jue, 17 feb 2022 a las 16:50, Ángela Carrillo (<acarrillo@excelcredit.co>) escribió a Febor: Cordial Saludo, Solicito su amable colaboración, procediendo con la suspensión o baja de descuento, del cliente en relación; teniendo en cuenta que le generamos compra de cartera. *Se adjunta soporte de pago y paz y salvo Cliente: WULFRAN ENRIQUE LOPEZ OJEDA C.c :3726870 Pagaduría: COLPENSIONES Febor responde lo siguiente: Buenas tardes Por medio de la presente nos permitimos informar que: 1.El paz y salvo adjunto no fue emitido por esta entidad cooperativa, ya que el asociado Wulfran Enrique lopez c.c. 3726870 tiene vigente el crédito Nª1192902 2.La persona que firma el certificado no es funcionario de Febor entidad cooperativa Por lo anterior no es procedente la solicitud en mención Acciones de la Cooperativa La Cooperativa mediante la jefatura jurídica inicia el debido proceso disciplinario con el asociado mencionado y se comunica a los funcionarios algunas recomendaciones importantes: 1 Recordemos que toda información de nuestros asociados es privada por tanto a ninguna persona, entidad, alto funcionario o quien quiera que solicite copias de cédulas, información de saldos, números de teléfono o demás NO es posible que lo brindemos incurrimos en una grave violación al deber de cuidado que tenemos con la autorización que nos brindan para proteger sus datos personales 2 Recordemos que las únicas firmas autorizadas para expedir certificaciones, paz y salvos y demás de este tipo son la dela Directora de Servicio al Asociado y el Gerente, por tanto generemos alerta inmediata cuando reciban llamadas para corroborar datos de este tipo de preguntar: fecha de la certificación, y quien la firma. Para control de todos considero importante que puedan incluir en pie de firma quien elaboró la certificación. 3 Proceso disciplinario - llamado de atención evaluado por la Junta de Vigilancia y el Consejo de Administración. 4 El Consejo de Administración decidió hacerle proceso de exclusión una vez que esté en firme el embargo de la mesada pensional. Sesión de Consejo 26 de noviembre 2022 | I13: 0 | J13: 0 | K13: 0 | L13: 1 - Fraude Interno | M13: 12 - Hurto y Fraude | N13: 125 Falsificación | O13: Ninguna | P13: 44620 | Q13: Crédito de consumo | R13: Canales de comunicación virtual | S13: 1020809741 | T13: Laura Nataly Arévalo Agredo | U13: asesor.sas9@febor.coop | V13: Aprobado | W13: 21/02/2022 14:24:58: Es importante en cada gestión que se realice en casos similares, tener las precauciones de revisar detalladamente la información y documentación recibida, confirmar hasta estar completamente seguro de que el proceso es real y transparente, dado que podrían existir métodos de falsificación de mayor nivel con dificultad de detección. | X13: Falsificación de documentos por parte de un asociado | Z13: =+COUNTIF('Eventos-Tareas'!$D$22:$D$1048576,'Eventos de riesgos'!$B13) -> 1 | AA13: =+'Eventos de riesgos'!$I13-'Eventos de riesgos'!$J13-'Eventos de riesgos'!$K13 -> 0 | AB13: Un asociado presentó paz y salvo falsificado ante la entidad Excelcredit para gestionar compra de cartera, utilizando firmas de personas ajenas a Febor. El documento fue validado sin detección del fraude, exponiendo a la Cooperativa a riesgo de cartera. | AC13: El asociado Wulfran Enrique López Ojeda presentó ante Excelcredit un paz y salvo falsificado a nombre de Febor sobre dos productos de crédito, firmado por una persona que no pertenece a la Cooperativa, con el fin de realizar una compra de cartera. | AD13: Falsificación de documentos por parte del asociado, aprovechando la ausencia de controles cruzados entre Febor y terceras entidades en la validación de paz y salvos para procesos de compra de cartera. | AE13: Riesgo de cartera para Febor por la posible suspensión del descuento de nómina. Exposición reputacional por uso fraudulento de documentos institucionales. Se requirió tramitación jurídica para aclarar la situación.
B14: 13 | C14: 2022 | D14: Abr | E14: 44655.406 | F14: 44656.406 | G14: 44655.406 | H14: Caso El día 4 de abril se detectaron errores en el sistema transaccional y en general de varios módulos de operación en Wog, debido a que este sistema tuvo cambio de versión el fin de semana (2 y 3 de abril) por la incorporación del modelo de originación en la fabrica de créditos. No se presentaron pérdidas económicas, ni se afectaron productos de los asociados ya que durante la ocurrencia se daba solución a las novedades por parte del área de tecnología y operaciones. Acciones Comunicación inmediata con el proveedor para la corrección de reportes y módulos afectados. El proveedor debe informar las actualizaciones y cambios de versión antes y prevenir a la entidad de los posibles daños. | I14: 0 | J14: 0 | K14: 0 | L14: 6 - Fallas Tecnologicas | M14: 61 - Sistemas | N14: 611 - Pérdida por Problemas en Software | O14: Ninguna | P14: 44681 | Q14: Ninguno | R14: Ninguno | S14: 1033706838 | T14: Diana Maribel Fonseca Gómez | U14: direccion.riesgos@febor.coop | V14: Aprobado | W14: 05/04/2022 09:47:50: Evento registrado desde el área de riesgos | X14: Errores por actualizaciones en Wog | Z14: =+COUNTIF('Eventos-Tareas'!$D$22:$D$1048576,'Eventos de riesgos'!$B14) -> 1 | AA14: =+'Eventos de riesgos'!$I14-'Eventos de riesgos'!$J14-'Eventos de riesgos'!$K14 -> 0 | AB14: El cambio de versión del sistema Wog durante el fin de semana generó errores en múltiples módulos operativos el día hábil siguiente, afectando temporalmente la operación. No se presentaron pérdidas ni afectación de productos de asociados. | AC14: El 4 de abril se detectaron errores en el sistema transaccional Wog y en varios módulos de operación, como consecuencia de un cambio de versión realizado durante el fin de semana del 2 y 3 de abril por la incorporación del modelo de originación en la fábrica de créditos. | AD14: Actualización de versión del sistema Wog sin pruebas previas suficientes ni comunicación anticipada a las áreas usuarias sobre los posibles impactos y errores esperados tras la implementación. | AE14: Errores en múltiples módulos del sistema transaccional durante el día hábil posterior al cambio. No se registraron pérdidas económicas ni afectación de productos de asociados, pero se generó sobrecarga operativa en las áreas de tecnología y operaciones.
B15: 14 | C15: 2022 | D15: May | E15: 44686.899 | F15: 44687.899 | G15: 44687.899 | H15: Caso Se presenta un caso de inconformidad por fallas en el proceso de consignación por cheque y tiempo de espera en la liberación de canje el 6 de mayo 2022. Mensaje del asociado Marco a la Gerencia: El pasado lunes, aproximadamente a la una de la tarde, consigné en la oficina de Febor del edificio anexo un cheque de gerencia para ser abonado a la cuenta de ahorros voluntarios, por valor de 82 millones. Considerando que el canje debe tardar, a lo sumo, 3 días, ayer jueves en la tarde le solicité vía WhatsApp a Jorge Lievano que del producto de esa consignación me hiciera el favor de hacer un pago por $80 millones a capital del crédito de reestructuración solidaria, Jorge me contesta después de unos minutos que el cheque todavía no ha sido confirmado el canje, yo le hice la observación en el sentido que consideraba que desde el lunes no era razonable que el canje no se hubiera dado, cuando se sabe que el canje normalmente demora 2 días. Hoy viernes alrededor de medio día volví a preguntarle a Jorge sobre la operación, me comentó que él estaba pendiente, pero que contabilidad, u operaciones todavía no le daba conformidad sobre el canje del cheque, a lo que volví a hacerle la observación sobre que no encontraba razonable tanta demora en el canje. Ante esta nueva situación, decidí llamar a Teresita y pedirle que me colaborara, hasta que finalmente hace un rato Jorge me confirmó que la operación de pago al crédito se hizo. El caso es que si yo no estoy pendiente e indagando, la plata queda depositada en la cuenta de Febor por varios días, sin aplicar ni a mi cuenta de ahorros voluntarios, ni para hacer el pago al crédito y por supuesto al no darse ese pago se causan intereses sobre mi crédito sin tener en cuenta que la plata ya está en poder de Febor desde hace varios días; sino hubiera estado yo pendiente la operación hubiera quedado para la semana entrante. En mi caso, porque tengo la posibilidad de llamar a Teresita y solicitarle colaboración, veo que Jorge no tiene culpa, porque el fué diligente cuando yo le hice la solicitud, simplemente él no podía hacer la operación mientras no le dieran la conformidad del canje. ________________ Se evalúa con el área de operaciones si el canje lo libera automáticamente el sistema, y si tiene un funcionario responsable de su verificación, además de definir el tiempo que debe durar en canje el cheque, que sea estrictamente lo necesario (máx. 3 días) Acciones El sistema tiene programados los días de liberar los cheques de canje (3 días), se ordena por parte de Gerencia disminuir los días a (1) en el sistema | I15: 0 | J15: 0 | K15: 0 | L15: 7 - Ejecución y Administración de Procesos | M15: 71 - Recepción, Ejecución y Mantenimiento de Operaciones | N15: 713 - Incumplimiento de Plazos o Responsabilidades | O15: Ninguna | P15: 44712 | Q15: Ahorros voluntarios | R15: Buzón Quejas y Reclamos | S15: 1033706838 | T15: Diana Maribel Fonseca Gómez | U15: direccion.riesgos@febor.coop | V15: Aprobado | W15: 07/05/2022 21:38:37: Información tomada de la presentación del caso por el grupo de dirección en WhatsApp por parte de la Gerencia | X15: Demoras en canje de cheques de asociados | Z15: =+COUNTIF('Eventos-Tareas'!$D$22:$D$1048576,'Eventos de riesgos'!$B15) -> 1 | AA15: =+'Eventos de riesgos'!$I15-'Eventos de riesgos'!$J15-'Eventos de riesgos'!$K15 -> 0 | AB15: Un asociado expresó inconformidad ante la Gerencia por demoras en la liberación del canje de un cheque de $82 millones consignado en la oficina. El proceso de consignación presentó fallas en el tiempo de respuesta y en la comunicación con el asociado. | AC15: El asociado Marco manifestó inconformidad por fallas en el proceso de consignación de un cheque de gerencia por $82 millones y por el tiempo de espera en la liberación del canje, que superó los 3 días habituales. | AD15: Demoras en el proceso de confirmación del canje bancario y falta de comunicación proactiva hacia el asociado sobre el estado de su operación, generando insatisfacción y escalamiento a la Gerencia. | AE15: Inconformidad del asociado y afectación en la percepción del servicio. El asociado no pudo realizar operaciones con los recursos de la consignación dentro del tiempo esperado, evidenciando debilidades en el proceso de canje y en los tiempos de respuesta al cliente.
B16: 15 | C16: 2022 | D16: Abr | E16: 44679.722 | F16: 44679.722 | G16: 44679.722 | H16: Caso El señor Luis Eduardo Rosales, ciudadano no asociado a la Cooperativa presento una queja ante la SES , inconforme por recibir correos con extractos bancarios que no le corresponden, pero que si le corresponden al asociado Luis Eduardo Rosales. La confusión consiste en envio de correo errado a luiseduardorosales@gmail.com y el correcto es luiseduardorosales08@gmail.com. Acciones A. La funcionaria Rina Herrera se comunicó con el asociado Luis Eduardo Rosales y efectivamente el correo de él es luiseduardorosales08@gmail.com, adicional contactará al señor Luis Rosales y se le indicará que no va a volver a recibir estos correos por parte de Febor Entidad Cooperativa. Se verifica sistema de encriptación frente a Base social, para que el problema sea solucionado de raíz, actualizándolo en el sistema Wog. Se verifica uno a uno los asociados a los que se les envío extractos de tarjeta crédito, para constatar que no hubo más inconsistencias, lo cual solo se presentó con este asociado. Se dio respuesta a la queja del ciudadano con conocimiento de la Junta de vigilancia y con copia a la Superintendencia de Economía Solidaria. | I16: 0 | J16: 0 | K16: 0 | L16: 7 - Ejecución y Administración de Procesos | M16: 71 - Recepción, Ejecución y Mantenimiento de Operaciones | N16: 719 - Seguridad de la Información | O16: Ninguna | P16: 44681 | Q16: Tarjeta crédito | R16: Buzón Quejas y Reclamos | S16: 1033706838 | T16: Diana Maribel Fonseca Gómez | U16: direccion.riesgos@febor.coop | V16: Aprobado | W16: 24/05/2022 17:21:30: La queja respuesta se proyecta, se traslada a junta de vigilancia para ser respondida al ciudadano con copia a la SES | X16: Manejo de datos personales | Z16: =+COUNTIF('Eventos-Tareas'!$D$22:$D$1048576,'Eventos de riesgos'!$B16) -> 2 | AA16: =+'Eventos de riesgos'!$I16-'Eventos de riesgos'!$J16-'Eventos de riesgos'!$K16 -> 0 | AB16: Se envió por error extractos bancarios de un asociado al correo de un tercero no vinculado a Febor, quien presentó queja ante la SES por recibir información que no le correspondía, evidenciando una falla en la gestión de datos de contacto. | AC16: Extractos bancarios del asociado Luis Eduardo Rosales fueron enviados al correo incorrecto luiseduardorosales@gmail.com en lugar del correcto luiseduardorosales08@gmail.com, siendo recibidos por un ciudadano no asociado que radicó queja ante la SES. | AD16: Error en el registro del correo electrónico del asociado en el sistema, sumado a la ausencia de controles de validación en el proceso de envío de extractos. | AE16: Exposición de información financiera confidencial de un asociado a un tercero no autorizado. Queja ante la SES por parte del ciudadano afectado. Riesgo de incumplimiento normativo en protección de datos personales.
B17: 16 | C17: 2022 | D17: May | E17: 44702.542 | F17: 44703.438 | G17: 44705.875 | H17: Caso Se presenta desconexión del servicio entre visionamos - Empacto - WOG el día 21 de mayo de 2022, que produce que las operaciones que los asociados realizaron con su tarjeta debito, su cuenta de ahorro, o sus cupos rotativos y avance no fueran registradas en el producto pero si fueron ejecutadas correctamente por visionamos y compensadas a Febor un total de 42 asociados. Diariamente se validan que las operaciones del día anterior sean ejecutadas en su totalidad en los productos correspondientes, el día Lunes 23 de mayo de 2022 se evidencian operaciones que presentan diferencias por lo cual se procede a remitir la información a contabilidad para validar si estas fueron compensadas por visionamos a febor. por parte de wog el 24 solicitan el envió el archivo AUT por medio del cual registran las operaciones que reporta visionamos y son cargados a los productos en WOG, una vez identifican las diferencias proceden a aplicarlas en producto con fecha 24 al cierre del día y en la descripción se diligencia que corresponden al 21 de mayo de 2022. Se debe validar la forma como monitorear en linea las desconexiones entre visionamos - Empacto - WOG, con el fin de realizar las acciones correctivas con mayor prontitud. Acciones Identifican las diferencias en los saldos y aplicar correcciones en el producto. | I17: 9649785 | J17: 9649785 | K17: 0 | L17: 6 - Fallas Tecnologicas | M17: 61 - Sistemas | N17: 614 - Interrupción en el Suministro de un Servicio Público que Ocasiones Falla en los Sistemas | O17: Ninguna | P17: 44712 | Q17: Ahorros voluntarios | R17: Ninguno | S17: 1018433978 | T17: Nataly Malagón | U17: operaciones@febor.coop | V17: Aprobado | W17: 25/05/2022 15:55:14: Reporte Evento SARO link 26/05/2022 12:36:41: Caso recibido, revisado por Dirección Riesgos | X17: Falla en operaciones electrónicas originadas por el proveedor | Z17: =+COUNTIF('Eventos-Tareas'!$D$22:$D$1048576,'Eventos de riesgos'!$B17) -> 1 | AA17: =+'Eventos de riesgos'!$I17-'Eventos de riesgos'!$J17-'Eventos de riesgos'!$K17 -> 0 | AB17: Desconexión entre Visionamos, Empacto y Wog el 21 de mayo de 2022 impidió que 42 operaciones realizadas con tarjeta débito, ahorros y cupos rotativos fueran registradas oportunamente en los productos correspondientes de los asociados. | AC17: El 21 de mayo de 2022 se presentó desconexión entre los sistemas Visionamos, Empacto y Wog, lo que impidió que las operaciones realizadas por 42 asociados con tarjeta débito, cuenta de ahorro y cupos rotativos fueran registradas correctamente en sus productos. | AD17: Falla en la integración tecnológica entre los sistemas transaccionales de los proveedores Visionamos, Empacto y el core Wog, lo que generó diferencias entre las operaciones compensadas y las registradas. | AE17: 42 asociados vieron afectado el registro de sus operaciones en los productos financieros. Se requirió intervención del área contable y de operaciones para conciliar y corregir los movimientos afectados.
B18: 17 | C18: 2022 | D18: May | E18: 44704.5 | F18: 44712.792 | G18: 44704.542 | H18: Caso El pasado lunes 23 de mayo, nuestra cajera de Mazuren Laura Nataly Arevalo tuvo un descuadre en cajera por $1.100.000- el mismo día al cierre luego de haber hecho todos los cruces respectivos informo del faltante y aseguro saber a que asociada le habia dado el dinero de mas, así mismo, informo que la llamo y la sra informo no tener el dinero de sobra. El martes 24 nuestra asociada se acerco a la oficina del centro y entrego un millón de pesos. Al revisar el video del momento de la atención en caja de la asociada, no se evidencia cual pudo haber sido la falla puntual, sin embargo considero que pudo darse por que la asesora tenia dinero en la maquina contadora. Valga le pena mencionar que es la primera vez que se presenta un descuadre en cabeza de nuestra asesora Laura Nataly Arevalo quien es la encargada de la caja desde 01 de septiembre en nuestra extensión de caja de Mazuren. Acciones Recuperación y devolución del dinero a la caja. Esta tarea la debe realizar la asesora Nataly Arévalo. | I18: 1100000 | J18: 1100000 | K18: 0 | L18: 7 - Ejecución y Administración de Procesos | M18: 71 - Recepción, Ejecución y Mantenimiento de Operaciones | N18: 718 - Error en Otras Tareas, Falla en la Entrega | O18: Ninguna | P18: 44712 | Q18: Ninguno | R18: Atención en oficina (caja) | S18: 53166187 | T18: Johana Cortés | U18: direccion.sas@febor.coop | V18: Aprobado | W18: 31/05/2022 07:37:29: Reporte Evento SARO link 01/06/2022 10:24:23: Se sugiere que el cajero tenga claro su procedimiento de operación en caja: 1. Se atiende un asociado a la vez 2. Se ingresa el dinero , se cuenta se guarda y se realiza la operación ( no dejar dinero en la maquina contadora) 3. Si se entrega dinero, grabar la operación, tomar el dinero, contarlo en la maquina, entregarlo y solicitar al asociado que confirme la cantidad entregada 4. Evitar distracciones durante las operaciones en caja (celulares, hablar con compañeros o demás visitantes etc.) | X18: Descuadre en caja | Z18: =+COUNTIF('Eventos-Tareas'!$D$22:$D$1048576,'Eventos de riesgos'!$B18) -> 1 | AA18: =+'Eventos de riesgos'!$I18-'Eventos de riesgos'!$J18-'Eventos de riesgos'!$K18 -> 0 | AB18: La cajera de la oficina Mazurén presentó un faltante de $1.100.000 al cierre del día por error en la entrega de efectivo a una asociada. El dinero fue recuperado parcialmente ($1.000.000) al día siguiente. | AC18: La cajera Laura Nataly Arévalo de la oficina Mazurén presentó un faltante de $1.100.000 al cierre del día 23 de mayo, identificando haber entregado por error dinero de más a una asociada. | AD18: Error humano en el manejo de efectivo durante la atención en caja, posiblemente asociado a la manipulación de dinero en la máquina contadora mientras se atendía a la asociada. | AE18: Faltante de $1.100.000 en caja. Se recuperaron $1.000.000 al día siguiente cuando la asociada los devolvió voluntariamente, quedando un faltante residual de $100.000.
B19: 18 | C19: 2022 | D19: May | E19: 44711.635 | F19: 44711.636 | G19: 44712.917 | H19: Caso Fallas en los sistemas retrasan la operación por casi dos horas, esto se debe a que se ejecutaron varios procesos masivos al tiempo y dado que los dos apuntan directamente a la base de datos, se estaban cargando créditos al mismo tiempo y adicionalmente se estaban procesando los archivos de Tarjeta de Crédito (que provienen de ASNET) los cuales generaron conflicto con el procesamiento del servidor. Al contactar con urgencia al proveedor WOG para solucionar el conflicto se tuvo los siguientes inconvenientes: Falta de soporte y prontitud del proveedor en las respuestas de solución. Burocracia en la toma de decisiones por parte del proveedor para la solución inmediata del problema. Esta afectación se evidencia por falta de monitoreo por parte del proveedor WOG, dado que ellos son los que administran la aplicación y determinan los procesos que afectan en gran escala al sistema. Acciones Comunicación inmediata con el proveedor para la corrección de reportes y módulos afectados Verificar la capacidad del servidor, evaluar lo que se requiere para que el rendimiento del sistema no disminuya por la ejecución de varios procesos. | I19: 0 | J19: 0 | K19: 0 | L19: 6 - Fallas Tecnologicas | M19: 61 - Sistemas | N19: 611 - Pérdida por Problemas en Software | O19: Ninguna | P19: 44712 | Q19: Varios tipos de crédito | R19: Ninguno | S19: 1010200415 | T19: Jasson Cepeda | U19: coordinador.informatica@febor.coop | V19: Aprobado | W19: 03/06/2022 12:24:42: Reporte Evento SARO link 05/06/2022 15:35:27: Desde el área de tecnología, se debe verificar la capacidad del servidor, evaluar lo que se requiere para que el rendimiento del sistema no disminuya por la ejecución de varios procesos. Se deben generar las recomendaciones preventivas para el buen manejo del sistema a los funcionarios con acceso a operaciones delicadas. | X19: Indisponibilidad Core Financiero Wog | Z19: =+COUNTIF('Eventos-Tareas'!$D$22:$D$1048576,'Eventos de riesgos'!$B19) -> 2 | AA19: =+'Eventos de riesgos'!$I19-'Eventos de riesgos'!$J19-'Eventos de riesgos'!$K19 -> 0 | AB19: La ejecución simultánea de múltiples procesos masivos sobre la base de datos del sistema WOG generó una interrupción de casi dos horas en la operación, agravada por la lentitud en la respuesta del proveedor para resolver la incidencia. | AC19: Se presentó una falla en el sistema Wog que detuvo la operación de la Cooperativa por casi dos horas, causada por la ejecución simultánea del cargue de créditos y el procesamiento de archivos de tarjeta de crédito provenientes de ASNET, generando conflicto en el servidor. | AD19: Ejecución de múltiples procesos masivos simultáneos que apuntaban directamente a la base de datos, sumada a la falta de monitoreo activo por parte del proveedor Wog y su demora en la atención y resolución de la incidencia. | AE19: Interrupción de la operación por aproximadamente dos horas. Afectación en la prestación del servicio a los asociados. Se evidenciaron debilidades en el soporte del proveedor Wog y en la coordinación ante contingencias tecnológicas.
B20: 19 | C20: 2022 | D20: May | E20: 44705.417 | F20: 44705.417 | G20: 44705.417 | H20: Caso El gerente Juan Pablo Vélez reporta como evento de riesgo la carencia y debilidad en el proceso de reporte de eventos de riesgo por parte de los funcionarios, a pesar de llevar a cabo capacitación al respecto, es necesario promover e intensificar el esfuerzo al respecto. Es necesario y obligatorio que todos los funcionarios conozcan el proceso y los medios para reportar eventos de riesgo y hacerlo de manera oportuna. Acciones Sensibilización a los funcionarios sobre el reporte de eventos de riesgo mediante cápsulas de conocimiento, reuniones con el personal y guía en la elaboración de reportes directamente a los jefes de área. | I20: 0 | J20: 0 | K20: 0 | L20: 7 - Ejecución y Administración de Procesos | M20: 72 - Seguimiento y Presentación de Informes | N20: 721 - Incumplimiento de la Obligación de Informar | O20: Ninguna | P20: 44712 | Q20: Ninguno | R20: Ninguno | S20: 72179606 | T20: Juan Pablo Vélez | U20: gerencia@febor.coop | V20: Aprobado | W20: 06/06/2022 14:19:46: El área de riesgos debe continuar fortaleciendo la cultura institucional basada en los procesos de riesgos. | X20: Empleados no reportan RO | Z20: =+COUNTIF('Eventos-Tareas'!$D$22:$D$1048576,'Eventos de riesgos'!$B20) -> 1 | AA20: =+'Eventos de riesgos'!$I20-'Eventos de riesgos'!$J20-'Eventos de riesgos'!$K20 -> 0 | AB20: Se identificó una debilidad estructural en el proceso de reporte de eventos de riesgo por parte de los funcionarios de Febor, a pesar de las capacitaciones realizadas, evidenciando baja apropiación de la cultura de gestión de riesgos. | AC20: La Gerencia identificó y reportó como evento de riesgo la carencia y debilidad en el proceso de reporte de eventos de riesgo por parte de los funcionarios, a pesar de las capacitaciones previas realizadas al respecto. | AD20: Insuficiente apropiación de la cultura de gestión de riesgos por parte del personal. Falta de sensibilización y conocimiento sobre los medios y la obligatoriedad del reporte oportuno de eventos. | AE20: Subregistro de eventos de riesgo que puede generar un panorama de riesgo incompleto para la Cooperativa. Dificultades para cumplir con las exigencias del SARO y para adoptar medidas preventivas y correctivas oportunas.
... B31: 30 | C31: 2022 | D31: Oct | E31: 44861.48 | F31: 44861.48 | G31: 44861.48 | H31: Caso Los asociados manifiestan que no pueden hacer pagos mediante la Cooperativa Digital porque no está en funcionamiento, no permite ingresar. Esta falla es escalada a Wog mediante la Jefe de Operaciones Nataly Malagón. (foto) Wog se encuentra en proceso de validación - pendiente cierre de la novedadSe activa el servicio nuevamente (foto) Acciones Reportar incidencia a Wog sobre las fallas presentadas en la Cooperativa Digital (Jefe de Operaciones) Seguimiento a la incidencia hasta comprobar que funcione correctamente la Cooperativa Digital (Jefe de Operaciones) | I31: 0 | J31: 0 | K31: 0 | L31: 6 - Fallas Tecnologicas | M31: 61 - Sistemas | N31: 611 - Pérdida por Problemas en Software | O31: Ninguna | P31: 44865 | Q31: Varios tipos de crédito | R31: Cooperativa Digital | S31: 53166187 | T31: JOHANA PAOLA CORTÉS GÓMEZ | U31: direccion.sas@febor.coop | V31: Aprobado | W31: 27/10/2022 11:32:36: Pendiente cambio de proceso afectado por configuración del sistema 27/10/2022 11:36:14: Cargue de seguimiento WOG 27/10/2022 11:53:27: Cierre de la falla operativa 27/10/2022 11:56:07: Cambio de canal afectado a Cooperativa Digital | X31: Fallas Cooperativa Digital | Z31: =+COUNTIF('Eventos-Tareas'!$D$22:$D$1048576,'Eventos de riesgos'!$B31) -> 2 | AA31: =+'Eventos de riesgos'!$I31-'Eventos de riesgos'!$J31-'Eventos de riesgos'!$K31 -> 0 | AB31: La plataforma Cooperativa Digital presentó fallas de acceso que impidieron a los asociados realizar pagos, afectando la prestación del servicio en el canal digital. La incidencia fue escalada a Wog para su solución. | AC31: Los asociados reportaron que no podían realizar pagos a través de la Cooperativa Digital debido a que la plataforma no permitía el ingreso, mostrando errores de acceso. | AD31: Falla técnica en la plataforma Cooperativa Digital administrada por el proveedor Wog, que generó indisponibilidad del canal para los asociados. | AE31: Imposibilidad de realizar pagos en línea para los asociados. Insatisfacción por la indisponibilidad del canal digital. Requirió escalamiento y seguimiento con el proveedor Wog para la reactivación del servicio.
B32: 31 | C32: 2022 | D32: Nov | E32: 44893.534 | F32: 44893.534 | G32: 44895.534 | H32: Caso Se recibió el retiro del asociado Helena Castro de Caicedo con CC 28.505.906 a razón del fallecimiento 10 de septiembre de 2022, cuya reclamación a la aseguradora fue aprobada a Febor el día 25 de noviembre, en el momento que se estaban realizando las validaciones correspondientes se evidencia que el día 28 de noviembre de 2022 se realizo un retiro de la cuenta del ahorro voluntario por valor de $1.143.000 a través de la cooperativa digital a la cuenta de Carmen Analida Caicedo Castro quien se encontraba inscrita como tercero de asociado fallecido. Por lo cual se evidencia que hay una suplantación de identidad y se conocían las credenciales de ingreso a la cooperativa digital con las cuales se realizo el fraude al asociado Q.E.P.D. Acciones Trámite jurídico, contacto con los familiares titulares (Jefe Jurídico) Modificación de procedimiento de retiro de asociados por fallecimiento, para analizar bloqueo de credenciales de asociados fallecidos para evitar transferencias de terceros por medio de la Cooperativa Digital.(Jefe de Operaciones) | I32: 1143000 | J32: 0 | K32: 0 | L32: 1 - Fraude Interno | M32: 11 - Actividades No Autorizadas | N32: 111 - Operaciones No Reveladas Intencionalmente | O32: Ninguna | P32: 44895 | Q32: Ahorros voluntarios | R32: Cooperativa Digital | S32: 1018433978 | T32: Natali Malagon Sierra | U32: operaciones@febor.coop | V32: Aprobado | X32: Retiro de ahorro de asociado fallecido | Z32: =+COUNTIF('Eventos-Tareas'!$D$22:$D$1048576,'Eventos de riesgos'!$B32) -> 2 | AA32: =+'Eventos de riesgos'!$I32-'Eventos de riesgos'!$J32-'Eventos de riesgos'!$K32 -> 1143000 | AB32: Se realizó un retiro fraudulento de $1.143.000 de la cuenta de ahorro de un asociado fallecido a través de la Cooperativa Digital, utilizando sus credenciales. El fraude fue ejecutado por un tercero inscrito como destinatario de transferencias. | AC32: El 28 de noviembre de 2022 se realizó un retiro de $1.143.000 desde la cuenta de ahorro voluntario del asociado fallecido Helena Castro de Caicedo a través de la Cooperativa Digital, hacia la cuenta de Carmen Analida Caicedo Castro, quien estaba inscrita como tercero. | AD32: Suplantación de identidad del asociado fallecido mediante el uso de sus credenciales de acceso a la Cooperativa Digital, posiblemente por un familiar que conocía los datos de acceso. | AE32: Pérdida de $1.143.000 de los recursos del asociado fallecido. Riesgo legal y reputacional para la Cooperativa. Se requirió trámite jurídico y contacto con los familiares para gestionar la situación.
B33: 32 | C33: 2022 | D33: Nov | E33: 44893.517 | F33: 44894.518 | G33: 44894.518 | H33: Caso El día 29 de noviembre el asociado Guillermo de comunicó a través del PBX sobre el medio día, informando que en la madrugada de ese mismo día se comunicaron de Coopcentral a confirmar si estaba realizando unas transferencias por 2 millones de pesos, donde el informó que no era él y de inmediato el banco le confirma el bloqueo de la cuenta. El banco le comenta que debe comunicarse con la cooperativa, al yo recibir la solicitud me acerque al área operativa para verificar la información y poderle brindar una respuesta al asociado el cual yo le informe que no se habían realizado las transferencias pero luego de realizar una verificación de movimientos se pudo corroborar que si se habían realizado dos retiros, le informe que monto tenía actualmente que correspondía a 800 mil pesos, efectivamente verificando Coopcentral había enviado un correo de aviso del fraude que se había evidenciado del asociado, le pregunté a Nataly jefe del área operativa que como podía manejar este caso en donde me responde que se va a reportar al banco para realizar seguimiento del caso y adicional que tocaba esperar la respuesta de ellos, luego el asociado me informo que precisamente el día de ayer (28 de noviembre) se había comunicado con una asesora de Febor para realizar el cambio de clave, le pregunte que si recordaba el nombre informando que no que le diera los nombres de mis compañeras y llegó a la conclusión de que lo atendió Laura Camila, y le realice varias preguntas sobre cómo había procedido Camila con el cambio de clave en donde me comenta que no recuerda si realizo el cambio de clave o le dejó la que ella le asignó, de igual manera le pregunte de que número se había comunicado el día anterior para poder buscar la conversación pero como se comunicó del teléfono del banco le informe que era un poco más complicado buscar dicha conversación pero que sin embargo íbamos a ponernos en la tarea de tratar de solucionar lo más pronto posible el inconveniente. Acciones Reconocimiento del dinero al asociado de manera inmediata para no generar mal malestar y mala imagen hacia Febor Tramitar con la aseguradora y Coopcentral para el retorno del dinero a Febor. El 04 de abril, la aseguradora solicitó a Febor los documentos que soportan la investigación del caso, el extracto de la cuenta de ahorros y la bitácora de movimientos, así como copia de las respuestas dadas por el Banco Cooperativo Concentrar y Visionamos. Tales documentos fueron recopilados y enviados a la aseguradora el 19 de abril bajo el radicado Siniestro Nro. 10270420 Caso OnBase 15918. A la fecha, no se ha obtenido respuesta. | I33: 4000000 | J33: 0 | K33: 0 | L33: 2 - Fraude Externo | M33: 22 - Hurto y Fraude | N33: 221 - Robo o Hurto | O33: Ninguna | P33: 44895 | Q33: Ahorros voluntarios | R33: Comunicación por PBX | S33: 1024558299 | T33: Manuela Vélez yara | U33: asesor.sas12@febor.coop | V33: Aprobado | X33: Suplantacion de Identidad y robo a asociados | Z33: =+COUNTIF('Eventos-Tareas'!$D$22:$D$1048576,'Eventos de riesgos'!$B33) -> 2 | AA33: =+'Eventos de riesgos'!$I33-'Eventos de riesgos'!$J33-'Eventos de riesgos'!$K33 -> 4000000 | AB33: Terceros realizaron transferencias no autorizadas de $1.200.000 desde la cuenta de ahorro del asociado Guillermo, mediante dos retiros sucesivos. El hecho fue reportado al asociado por Coopcentral y confirmado por Febor. | AC33: El 29 de noviembre, el asociado Guillermo reportó que en la madrugada se realizaron transferencias no autorizadas de su cuenta de ahorros voluntarios por un valor de $1.200.000 en dos retiros, hecho que fue alertado inicialmente por Coopcentral. | AD33: Acceso no autorizado a los productos del asociado por parte de terceros, quienes realizaron dos retiros sucesivos sin el conocimiento ni consentimiento del titular. | AE33: Pérdida de $1.200.000 de los recursos del asociado. El saldo restante en la cuenta era de $800.000. Se generó malestar en el asociado y riesgo reputacional para la Cooperativa por la seguridad de sus productos transaccionales.
